{"tag": "function", "depth": 1, "time": 1700143078.924225, "data": {"name": "connect_device", "call_args": {"uri": "android://127.0.0.1:5037/R3CW10C3D9N?cap_method=MINICAP&touch_method=MAXTOUCH&"}, "start_time": 1700143073.866692, "traceback": "Traceback (most recent call last):\n  File \"/Users/mac/opt/anaconda3/envs/CB/lib/python3.9/site-packages/airtest/core/android/adb.py\", line 336, in wait_for_device\n    self.cmd(\"wait-for-device\", timeout=timeout)\n  File \"/Users/mac/opt/anaconda3/envs/CB/lib/python3.9/site-packages/airtest/core/android/adb.py\", line 216, in cmd\n    stdout, stderr = proc_communicate_timeout(proc, timeout)\n  File \"/Users/mac/opt/anaconda3/envs/CB/lib/python3.9/site-packages/airtest/utils/compat.py\", line 79, in proc_communicate_timeout\n    raise_from(exp, None)\n  File \"<string>\", line 3, in raise_from\nRuntimeError: Command ['/Applications/AirtestIDE.app/Contents/MacOS/airtest/core/android/static/adb/mac/adb', '-P', '5037', '-s', 'R3CW10C3D9N', 'wait-for-device'] timed out after 5 seconds: stdout['b'''], stderr['b''']\n\nThe above exception was the direct cause of the following exception:\n\nTraceback (most recent call last):\n  File \"/Users/mac/opt/anaconda3/envs/CB/lib/python3.9/site-packages/airtest/utils/logwraper.py\", line 131, in wrapper\n    res = f(*args, **kwargs)\n  File \"/Users/mac/opt/anaconda3/envs/CB/lib/python3.9/site-packages/airtest/core/api.py\", line 74, in connect_device\n    dev = init_device(platform, uuid, **params)\n  File \"/Users/mac/opt/anaconda3/envs/CB/lib/python3.9/site-packages/airtest/core/api.py\", line 42, in init_device\n    dev = cls(uuid, **kwargs)\n  File \"/Users/mac/opt/anaconda3/envs/CB/lib/python3.9/site-packages/airtest/core/android/android.py\", line 58, in __init__\n    self.adb.wait_for_device()\n  File \"/Users/mac/opt/anaconda3/envs/CB/lib/python3.9/site-packages/airtest/core/android/adb.py\", line 338, in wait_for_device\n    raisefrom(DeviceConnectionError, \"device not ready\", e)\n  File \"/Users/mac/opt/anaconda3/envs/CB/lib/python3.9/site-packages/airtest/utils/compat.py\", line 55, in raisefrom\n    raise_from(exc_type(message), exc)\n  File \"<string>\", line 3, in raise_from\nairtest.core.error.DeviceConnectionError: 'device not ready'\n", "end_time": 1700143078.924174}}
